[2022-06-20 08:27:08,898] {taskinstance.py:1159} INFO - Dependencies all met for <TaskInstance: scenario_insert_only.run_this manual__2022-06-20T08:27:07.802097+00:00 [queued]>
[2022-06-20 08:27:08,919] {taskinstance.py:1159} INFO - Dependencies all met for <TaskInstance: scenario_insert_only.run_this manual__2022-06-20T08:27:07.802097+00:00 [queued]>
[2022-06-20 08:27:08,921] {taskinstance.py:1356} INFO - 
--------------------------------------------------------------------------------
[2022-06-20 08:27:08,922] {taskinstance.py:1357} INFO - Starting attempt 1 of 1
[2022-06-20 08:27:08,923] {taskinstance.py:1358} INFO - 
--------------------------------------------------------------------------------
[2022-06-20 08:27:08,949] {taskinstance.py:1377} INFO - Executing <Task(BashOperator): run_this> on 2022-06-20 08:27:07.802097+00:00
[2022-06-20 08:27:08,956] {standard_task_runner.py:52} INFO - Started process 489 to run task
[2022-06-20 08:27:08,961] {standard_task_runner.py:79} INFO - Running: ['***', 'tasks', 'run', 'scenario_insert_only', 'run_this', 'manual__2022-06-20T08:27:07.802097+00:00', '--job-id', '11', '--raw', '--subdir', 'DAGS_FOLDER/scenario_insert_only.py', '--cfg-path', '/tmp/tmpbs66g6nc', '--error-file', '/tmp/tmp0yqshf0x']
[2022-06-20 08:27:08,963] {standard_task_runner.py:80} INFO - Job 11: Subtask run_this
[2022-06-20 08:27:09,041] {task_command.py:370} INFO - Running <TaskInstance: scenario_insert_only.run_this manual__2022-06-20T08:27:07.802097+00:00 [running]> on host d7f065c79af8
[2022-06-20 08:27:09,139] {taskinstance.py:1571} INFO - Exporting the following env vars:
AIRFLOW_CTX_DAG_OWNER=Airflow
AIRFLOW_CTX_DAG_ID=scenario_insert_only
AIRFLOW_CTX_TASK_ID=run_this
AIRFLOW_CTX_EXECUTION_DATE=2022-06-20T08:27:07.802097+00:00
AIRFLOW_CTX_TRY_NUMBER=1
AIRFLOW_CTX_DAG_RUN_ID=manual__2022-06-20T08:27:07.802097+00:00
[2022-06-20 08:27:09,142] {subprocess.py:62} INFO - Tmp dir root location: 
 /tmp
[2022-06-20 08:27:09,145] {subprocess.py:74} INFO - Running command: ['bash', '-c', 'python /opt/***/dags/script/transfer_case_insert_only.py']
[2022-06-20 08:27:09,159] {subprocess.py:85} INFO - Output:
[2022-06-20 08:27:09,408] {subprocess.py:92} INFO - relation "transactions" already exists
[2022-06-20 08:27:09,410] {subprocess.py:92} INFO - 
[2022-06-20 08:27:09,411] {subprocess.py:92} INFO - database X:
[2022-06-20 08:27:09,413] {subprocess.py:92} INFO - column "none" does not exist
[2022-06-20 08:27:09,414] {subprocess.py:92} INFO - LINE 1: ...ion_date, sale_value FROM transactions WHERE id > None ORDER...
[2022-06-20 08:27:09,415] {subprocess.py:92} INFO -                                                              ^
[2022-06-20 08:27:09,416] {subprocess.py:92} INFO - 
[2022-06-20 08:27:09,418] {subprocess.py:92} INFO - []
[2022-06-20 08:27:09,419] {subprocess.py:92} INFO - insert list transaction successful
[2022-06-20 08:27:09,421] {subprocess.py:96} INFO - Command exited with return code 0
[2022-06-20 08:27:09,486] {taskinstance.py:1400} INFO - Marking task as SUCCESS. dag_id=scenario_insert_only, task_id=run_this, execution_date=20220620T082707, start_date=20220620T082708, end_date=20220620T082709
[2022-06-20 08:27:09,539] {local_task_job.py:156} INFO - Task exited with return code 0
[2022-06-20 08:27:09,616] {local_task_job.py:273} INFO - 0 downstream tasks scheduled from follow-on schedule check
